<?xml version="1.0" encoding="utf-8"?>
<!-- =================================================================================== -->
<!-- |    This document was autogenerated by xacro from m6.urdf.xacro                  | -->
<!-- |    EDITING THIS FILE BY HAND IS NOT RECOMMENDED                                 | -->
<!-- =================================================================================== -->
<robot name="m6">
  <material name="red">
    <color rgba="0.92 0.0 0.0 1"/>
  </material>
  <material name="black">
    <color rgba="0.2 0.2 0.2 1"/>
  </material>
  <material name="grey">
    <color rgba="0.6 0.6 0.6 1"/>
  </material>
  <!-- <link name="dummy">
  </link>

  <joint name="dummy_joint" type="fixed">
  <parent link="dummy"/>
  <child link="base_link"/>
  </joint> -->
  <link name="base_link">
    <inertial>
      <origin rpy="0 0 0 " xyz="-0.0028085 -0.0003448 0.0270705"/>
      <mass value="1.8476"/>
      <inertia ixx="0" ixy="0" ixz="0" iyy="0" iyz="0" izz="0"/>
    </inertial>
    <visual>
      <origin rpy="0 0 0" xyz="0 0 0"/>
      <geometry>
        <mesh filename="yuna_stl/M6_base_matt6_boxed_full.STL"/>
      </geometry>
      <material name="black">
      </material>
    </visual>
    <collision>
      <origin rpy="0.0 0.0 0.0" xyz="-0.020030 0.0 0.09"/>
      <geometry>
        <box size="0.261940 0.223 0.18"/>
      </geometry>
    </collision>
    <collision>
      <origin rpy="0.0 0.0 0.0" xyz="0.0 0.0 -0.0335"/>
      <geometry>
        <cylinder length="0.063" radius="0.0777"/>
      </geometry>
    </collision>
    <!-- Pipes below PC box -->
    <collision>
      <origin rpy="0.523583333333 1.57075 0.0" xyz="0.1209 -0.06985 -0.02"/>
      <geometry>
        <cylinder length="0.126" radius="0.015800"/>
      </geometry>
    </collision>
    <collision>
      <origin rpy="-0.523583333333 1.57075 0.0" xyz="0.1209 0.06985 -0.02"/>
      <geometry>
        <cylinder length="0.126" radius="0.015800"/>
      </geometry>
    </collision>
    <collision>
      <origin rpy="0.523583333333 1.57075 0.0" xyz="-0.1209 0.06985 -0.02"/>
      <geometry>
        <cylinder length="0.126" radius="0.015800"/>
      </geometry>
    </collision>
    <collision>
      <origin rpy="-0.523583333333 1.57075 0.0" xyz="-0.1209 -0.06985 -0.02"/>
      <geometry>
        <cylinder length="0.126" radius="0.015800"/>
      </geometry>
    </collision>
    <collision>
      <origin rpy="1.57075 1.57075 0.0" xyz="0.0 0.1147 -0.02"/>
      <geometry>
        <cylinder length="0.076" radius="0.015800"/>
      </geometry>
    </collision>
    <collision>
      <origin rpy="1.57075 1.57075 0.0" xyz="0.0 -0.1147 -0.02"/>
      <geometry>
        <cylinder length="0.076" radius="0.015800"/>
      </geometry>
    </collision>
    <!-- Boxes at the end of pipes -->
    <collision>
      <origin rpy="0.0 0.0 0.523583333333" xyz="0.20802 0.1201 -0.023"/>
      <geometry>
        <box size="0.073 0.075 0.046"/>
      </geometry>
    </collision>
    <collision>
      <origin rpy="0.0 0.0 -0.523583333333" xyz="0.20802 -0.1201 -0.023"/>
      <geometry>
        <box size="0.073 0.075 0.046"/>
      </geometry>
    </collision>
    <collision>
      <origin rpy="0.0 0.0 0.523583333333" xyz="-0.20802 -0.1201 -0.023"/>
      <geometry>
        <box size="0.073 0.075 0.046"/>
      </geometry>
    </collision>
    <collision>
      <origin rpy="0.0 0.0 -0.523583333333" xyz="-0.20802 0.1201 -0.023"/>
      <geometry>
        <box size="0.073 0.075 0.046"/>
      </geometry>
    </collision>
    <collision>
      <origin rpy="0.0 0.0 1.57075" xyz="0.0 0.1902 -0.023"/>
      <geometry>
        <box size="0.073 0.075 0.046"/>
      </geometry>
    </collision>
    <collision>
      <origin rpy="0.0 0.0 1.57075" xyz="0.0 -0.1902 -0.023"/>
      <geometry>
        <box size="0.073 0.075 0.046"/>
      </geometry>
    </collision>
  </link>


  <joint name="leg1__OUTPUT_INTERFACE" type="fixed">
    <origin rpy="0 0 3.66508333333" xyz="0.205681 0.11875 0"/>
    <parent link="base_link"/>
    <child link="base1__INPUT_INTERFACE"/>
    <axis xyz="0 0 1"/>
    <limit effort="0" velocity="0"/>
  </joint>
    <link name="base1__INPUT_INTERFACE">
    <inertial>
      <origin rpy="0 0 0" xyz="0.015005 0.001775 0.015011"/>
      <mass value="1.2804"/>
      <inertia ixx="0.000533112547871023" ixy="8.52907138161489E-05" ixz="6.73224445510202E-07" iyy="0.000959826064510336" iyz="8.0840859065961E-07" izz="0.00130175668733721"/>
    </inertial>
    <visual>
      <origin rpy="0 0 0" xyz="0 0 0.015"/>
      <geometry>
        <mesh filename="yuna_stl/M6_base_motor.STL"/>
      </geometry>
      <material name="red">
      </material>
    </visual>
    <collision>
      <!--origin
          xyz="0 0 0.015"
          rpy="0 0 0" />
        <geometry>
          <mesh
            filename="yuna_stl/boxed_meshes/base_motor.STL" />
        </geometry-->
      <origin rpy="0 0 0" xyz="0.019940 0.001750 0.015525"/>
      <geometry>
        <box size="0.106400 0.069500 0.031050"/>
      </geometry>
    </collision>
  </link>
  <link name="shoulder1__INPUT_INTERFACE">
    <inertial>
      <origin rpy="0 0 0" xyz="-0.012554 -0.0090693 0.0503697"/>
      <mass value="1.4679"/>
      <inertia ixx="0.00085304" ixy="-4.463E-05" ixz="4.178E-05" iyy="0.0016596" iyz="4.4E-06" izz="0.00113592"/>
    </inertial>
    <visual>
      <origin rpy="0 0 0" xyz="0 0 0"/>
      <geometry>
        <mesh filename="yuna_stl/M6_left_link1_red.STL"/>
      </geometry>
      <material name="grey">
      </material>
    </visual>
    <collision>
      <!--origin
          xyz="0 0 0"
          rpy="0 0 0" />
        <geometry>
          <mesh
            filename="yuna_stl/boxed_meshes/left_link1_red.STL" />
        </geometry-->
      <origin rpy="0 0 0" xyz="-0.019070 -0.014470 0.052500"/>
      <geometry>
        <box size="0.108140 0.04500 0.104000"/>
      </geometry>
    </collision>
  </link>
  <joint name="base1" type="revolute">
    <origin rpy="0 0 3.1415" xyz="0 0 0.03105"/>
    <parent link="base1__INPUT_INTERFACE"/>
    <child link="shoulder1__INPUT_INTERFACE"/>
    <axis xyz="0 0 1"/>
    <dynamics damping=".1" friction="0.2"/>
    <limit effort="100.0" lower="-1.57075" upper="1.57075" velocity="2.208932"/>
  </joint>
  <transmission name="base1_trans">
    <type>transmission_interface/SimpleTransmission</type>
    <joint name="base1">
      <hardwareInterface>hardware_interface/EffortJointInterface</hardwareInterface>
    </joint>
    <actuator name="base1_motor">
      <hardwareInterface>hardware_interface/EffortJointInterface</hardwareInterface>
      <mechanicalReduction>300</mechanicalReduction>
    </actuator>
  </transmission>
  <link name="elbow1__INPUT_INTERFACE">
    <inertial>
      <origin rpy="0 0 0" xyz="0.27885723 0.00143862 -0.00919708"/>
      <mass value="1.58985"/>
      <inertia ixx="0.00087813" ixy="-2.653E-05" ixz="-0.00101493" iyy="0.01121522" iyz="-1.36E-05" izz="0.01137087"/>
    </inertial>
    <visual>
      <origin rpy="0 0 0" xyz="0 0 0"/>
      <geometry>
        <mesh filename="yuna_stl/M6_link2_red.STL"/>
      </geometry>
      <material name="red">
      </material>
    </visual>
    <collision>
      <!--origin
          xyz="0 0 0"
          rpy="0 0 0" />
        <geometry>
          <mesh
            filename="yuna_stl/boxed_meshes/link2_red.STL" />
        </geometry-->
      <origin rpy="0 0 0" xyz="0.005750 0.0 0.018750"/>
      <geometry>
        <box size="0.05950 0.04800 0.037500"/>
      </geometry>
    </collision>
    <collision>
      <origin rpy="0 1.57075 0" xyz="0.159500 0.0 0.02"/>
      <geometry>
        <cylinder length="0.246" radius="0.015811"/>
      </geometry>
    </collision>
    <collision>
      <origin rpy="0 0 0" xyz="0.317750 0.0 0.01875"/>
      <geometry>
        <box size="0.06850 0.06500 0.037500"/>
      </geometry>
    </collision>
    <collision>
      <origin rpy="0.0 0.0 0.0" xyz="0.299560 0.001750 -0.015520"/>
      <geometry>
        <box size="0.106400 0.069500 0.030050"/>
      </geometry>
    </collision>
  </link>
  <joint name="shoulder1" type="revolute">
    <origin rpy="-1.57075 0 0" xyz="0 0.00855 0.055"/>
    <parent link="shoulder1__INPUT_INTERFACE"/>
    <child link="elbow1__INPUT_INTERFACE"/>
    <axis xyz="0 0 1"/>
    <dynamics damping=".1" friction="0.2"/>
    <limit effort="100.0" lower="-1.57075" upper="1.57075" velocity="2.208932"/>
  </joint>
  <transmission name="shoulder1_trans">
    <type>transmission_interface/SimpleTransmission</type>
    <joint name="shoulder1">
      <hardwareInterface>hardware_interface/EffortJointInterface</hardwareInterface>
    </joint>
    <actuator name="shoulder1_motor">
      <hardwareInterface>hardware_interface/EffortJointInterface</hardwareInterface>
      <mechanicalReduction>300</mechanicalReduction>
    </actuator>
  </transmission>
  <link name="leg1__LAST_LINK">
    <inertial>
      <origin rpy="0 0 0" xyz="0.12121923 0 0.01723596"/>
      <mass value="0.229433"/>
      <inertia ixx="7.471E-05" ixy="0" ixz="7.798E-05" iyy="0.00331684" iyz="0" izz="0.0033262"/>
    </inertial>
    <visual>
      <origin rpy="0 0 0" xyz="0 0 0"/>
      <geometry>
        <mesh filename="yuna_stl/M6_link3_red.STL"/>
      </geometry>
      <material name="grey">
      </material>
    </visual>
    <!--collision>
        <origin
          xyz="0 0 0"
          rpy="0 0 0" />
        <geometry>
          <mesh
            filename="yuna_stl/boxed_meshes/link3_red.STL" />
        </geometry>
      </collision-->
    <collision>
      <origin rpy="0 0 0" xyz="0.00575 0.0 0.0185"/>
      <geometry>
        <box size="0.05850 0.04800 0.03650"/>
      </geometry>
    </collision>
    <collision>
      <origin rpy="0.0 1.57075 0.0" xyz="0.15125 0.000 0.020"/>
      <geometry>
        <cylinder length="0.230500" radius="0.015811"/>
      </geometry>
    </collision>
    <collision>
      <origin rpy="0.0 0.0 0.0" xyz="0.28950 0.00 0.02"/>
      <geometry>
        <box size="0.045000 0.047030 0.047030"/>
      </geometry>
    </collision>
  </link>
  <joint name="elbow1" type="revolute">
    <origin rpy="3.1415 0 0" xyz="0.3195 0 -0.03105"/>
    <parent link="elbow1__INPUT_INTERFACE"/>
    <child link="leg1__LAST_LINK"/>
    <axis xyz="0 0 1"/>
    <dynamics damping=".1" friction="0.2"/>
    <limit effort="100.0" lower="-3.1415" upper="3.1415" velocity="2.208932"/>
  </joint>
  <transmission name="elbow1_trans">
    <type>transmission_interface/SimpleTransmission</type>
    <joint name="elbow1">
      <hardwareInterface>hardware_interface/EffortJointInterface</hardwareInterface>
    </joint>
    <actuator name="elbow1_motor">
      <hardwareInterface>hardware_interface/EffortJointInterface</hardwareInterface>
      <mechanicalReduction>300</mechanicalReduction>
    </actuator>
  </transmission>
  <link name="leg1__FOOT">
    <visual>
      <origin rpy="0 0 0" xyz="0 0 0"/>
      <geometry>
        <sphere radius="0.02"/>
      </geometry>
      <material name="orange"/>
    </visual>
    <collision>
      <origin rpy="0 0 0" xyz="0 0 0"/>
      <geometry>
        <sphere radius="0.03"/>
      </geometry>
    </collision>
    <inertial>
      <origin rpy="0 0 0" xyz="0 0 0"/>
      <mass value="0.06"/>
      <inertia ixx="9.6e-06" ixy="0.0" ixz="0.0" iyy="9.6e-06" iyz="0.0" izz="9.6e-06"/>
    </inertial>
  </link>
  <joint name="leg1__FOOT_INTERFACE" type="fixed">
    <origin rpy="0 0 0" xyz="0.31 0 0.02"/>
    <parent link="leg1__LAST_LINK"/>
    <child link="leg1__FOOT"/>
    <axis xyz="0 0 1"/>
    <limit effort="0" velocity="0"/>
  </joint>
  <link name="base3__INPUT_INTERFACE">
    <inertial>
      <origin rpy="0 0 0" xyz="0.015005 0.001775 0.015011"/>
      <mass value="1.2804"/>
      <inertia ixx="0.000533112547871023" ixy="8.52907138161489E-05" ixz="6.73224445510202E-07" iyy="0.000959826064510336" iyz="8.0840859065961E-07" izz="0.00130175668733721"/>
    </inertial>
    <visual>
      <origin rpy="0 0 0" xyz="0 0 0.015"/>
      <geometry>
        <mesh filename="yuna_stl/M6_base_motor.STL"/>
      </geometry>
      <material name="red">
      </material>
    </visual>
    <collision>
      <!--origin
          xyz="0 0 0.015"
          rpy="0 0 0" />
        <geometry>
          <mesh
            filename="yuna_stl/boxed_meshes/base_motor.STL" />
        </geometry-->
      <origin rpy="0 0 0" xyz="0.019940 0.001750 0.015525"/>
      <geometry>
        <box size="0.106400 0.069500 0.031050"/>
      </geometry>
    </collision>
  </link>
  <joint name="leg3__OUTPUT_INTERFACE" type="fixed">
    <origin rpy="0 0 4.71225" xyz="0 0.1875 0"/>
    <parent link="base_link"/>
    <child link="base3__INPUT_INTERFACE"/>
    <axis xyz="0 0 1"/>
    <limit effort="0" velocity="0"/>
  </joint>
  <link name="shoulder3__INPUT_INTERFACE">
    <inertial>
      <origin rpy="0 0 0" xyz="-0.012554 -0.0090693 0.0503697"/>
      <mass value="1.4679"/>
      <inertia ixx="0.00085304" ixy="-4.463E-05" ixz="4.178E-05" iyy="0.0016596" iyz="4.4E-06" izz="0.00113592"/>
    </inertial>
    <visual>
      <origin rpy="0 0 0" xyz="0 0 0"/>
      <geometry>
        <mesh filename="yuna_stl/M6_left_link1_red.STL"/>
      </geometry>
      <material name="grey">
      </material>
    </visual>
    <collision>
      <!--origin
          xyz="0 0 0"
          rpy="0 0 0" />
        <geometry>
          <mesh
            filename="yuna_stl/boxed_meshes/left_link1_red.STL" />
        </geometry-->
      <origin rpy="0 0 0" xyz="-0.019070 -0.014470 0.052500"/>
      <geometry>
        <box size="0.108140 0.04500 0.104000"/>
      </geometry>
    </collision>
  </link>
  <joint name="base3" type="revolute">
    <origin rpy="0 0 3.1415" xyz="0 0 0.03105"/>
    <parent link="base3__INPUT_INTERFACE"/>
    <child link="shoulder3__INPUT_INTERFACE"/>
    <axis xyz="0 0 1"/>
    <dynamics damping=".1" friction="0.2"/>
    <limit effort="100.0" lower="-1.57075" upper="1.57075" velocity="2.208932"/>
  </joint>
  <transmission name="base3_trans">
    <type>transmission_interface/SimpleTransmission</type>
    <joint name="base3">
      <hardwareInterface>hardware_interface/EffortJointInterface</hardwareInterface>
    </joint>
    <actuator name="base3_motor">
      <hardwareInterface>hardware_interface/EffortJointInterface</hardwareInterface>
      <mechanicalReduction>300</mechanicalReduction>
    </actuator>
  </transmission>
  <link name="elbow3__INPUT_INTERFACE">
    <inertial>
      <origin rpy="0 0 0" xyz="0.27885723 0.00143862 -0.00919708"/>
      <mass value="1.58985"/>
      <inertia ixx="0.00087813" ixy="-2.653E-05" ixz="-0.00101493" iyy="0.01121522" iyz="-1.36E-05" izz="0.01137087"/>
    </inertial>
    <visual>
      <origin rpy="0 0 0" xyz="0 0 0"/>
      <geometry>
        <mesh filename="yuna_stl/M6_link2_red.STL"/>
      </geometry>
      <material name="red">
      </material>
    </visual>
    <collision>
      <!--origin
          xyz="0 0 0"
          rpy="0 0 0" />
        <geometry>
          <mesh
            filename="yuna_stl/boxed_meshes/link2_red.STL" />
        </geometry-->
      <origin rpy="0 0 0" xyz="0.005750 0.0 0.018750"/>
      <geometry>
        <box size="0.05950 0.04800 0.037500"/>
      </geometry>
    </collision>
    <collision>
      <origin rpy="0 1.57075 0" xyz="0.159500 0.0 0.02"/>
      <geometry>
        <cylinder length="0.246" radius="0.015811"/>
      </geometry>
    </collision>
    <collision>
      <origin rpy="0 0 0" xyz="0.317750 0.0 0.01875"/>
      <geometry>
        <box size="0.06850 0.06500 0.037500"/>
      </geometry>
    </collision>
    <collision>
      <origin rpy="0.0 0.0 0.0" xyz="0.299560 0.001750 -0.015520"/>
      <geometry>
        <box size="0.106400 0.069500 0.030050"/>
      </geometry>
    </collision>
  </link>
  <joint name="shoulder3" type="revolute">
    <origin rpy="-1.57075 0 0" xyz="0 0.00855 0.055"/>
    <parent link="shoulder3__INPUT_INTERFACE"/>
    <child link="elbow3__INPUT_INTERFACE"/>
    <axis xyz="0 0 1"/>
    <dynamics damping=".1" friction="0.2"/>
    <limit effort="100.0" lower="-1.57075" upper="1.57075" velocity="2.208932"/>
  </joint>
  <transmission name="shoulder3_trans">
    <type>transmission_interface/SimpleTransmission</type>
    <joint name="shoulder3">
      <hardwareInterface>hardware_interface/EffortJointInterface</hardwareInterface>
    </joint>
    <actuator name="shoulder3_motor">
      <hardwareInterface>hardware_interface/EffortJointInterface</hardwareInterface>
      <mechanicalReduction>300</mechanicalReduction>
    </actuator>
  </transmission>
  <link name="leg3__LAST_LINK">
    <inertial>
      <origin rpy="0 0 0" xyz="0.12121923 0 0.01723596"/>
      <mass value="0.229433"/>
      <inertia ixx="7.471E-05" ixy="0" ixz="7.798E-05" iyy="0.00331684" iyz="0" izz="0.0033262"/>
    </inertial>
    <visual>
      <origin rpy="0 0 0" xyz="0 0 0"/>
      <geometry>
        <mesh filename="yuna_stl/M6_link3_red.STL"/>
      </geometry>
      <material name="grey">
      </material>
    </visual>
    <!--collision>
        <origin
          xyz="0 0 0"
          rpy="0 0 0" />
        <geometry>
          <mesh
            filename="yuna_stl/boxed_meshes/link3_red.STL" />
        </geometry>
      </collision-->
    <collision>
      <origin rpy="0 0 0" xyz="0.00575 0.0 0.0185"/>
      <geometry>
        <box size="0.05850 0.04800 0.03650"/>
      </geometry>
    </collision>
    <collision>
      <origin rpy="0.0 1.57075 0.0" xyz="0.15125 0.000 0.020"/>
      <geometry>
        <cylinder length="0.230500" radius="0.015811"/>
      </geometry>
    </collision>
    <collision>
      <origin rpy="0.0 0.0 0.0" xyz="0.28950 0.00 0.02"/>
      <geometry>
        <box size="0.045000 0.047030 0.047030"/>
      </geometry>
    </collision>
  </link>
  <joint name="elbow3" type="revolute">
    <origin rpy="3.1415 0 0" xyz="0.3195 0 -0.03105"/>
    <parent link="elbow3__INPUT_INTERFACE"/>
    <child link="leg3__LAST_LINK"/>
    <axis xyz="0 0 1"/>
    <dynamics damping=".1" friction="0.2"/>
    <limit effort="100.0" lower="-3.1415" upper="3.1415" velocity="2.208932"/>
  </joint>
  <transmission name="elbow3_trans">
    <type>transmission_interface/SimpleTransmission</type>
    <joint name="elbow3">
      <hardwareInterface>hardware_interface/EffortJointInterface</hardwareInterface>
    </joint>
    <actuator name="elbow3_motor">
      <hardwareInterface>hardware_interface/EffortJointInterface</hardwareInterface>
      <mechanicalReduction>300</mechanicalReduction>
    </actuator>
  </transmission>
  <link name="leg3__FOOT">
    <visual>
      <origin rpy="0 0 0" xyz="0 0 0"/>
      <geometry>
        <sphere radius="0.02"/>
      </geometry>
      <material name="orange"/>
    </visual>
    <collision>
      <origin rpy="0 0 0" xyz="0 0 0"/>
      <geometry>
        <sphere radius="0.03"/>
      </geometry>
    </collision>
    <inertial>
      <origin rpy="0 0 0" xyz="0 0 0"/>
      <mass value="0.06"/>
      <inertia ixx="9.6e-06" ixy="0.0" ixz="0.0" iyy="9.6e-06" iyz="0.0" izz="9.6e-06"/>
    </inertial>
  </link>
  <joint name="leg3__FOOT_INTERFACE" type="fixed">
    <origin rpy="0 0 0" xyz="0.31 0 0.02"/>
    <parent link="leg3__LAST_LINK"/>
    <child link="leg3__FOOT"/>
    <axis xyz="0 0 1"/>
    <limit effort="0" velocity="0"/>
  </joint>
  <link name="base5__INPUT_INTERFACE">
    <inertial>
      <origin rpy="0 0 0" xyz="0.015005 0.001775 0.015011"/>
      <mass value="1.2804"/>
      <inertia ixx="0.000533112547871023" ixy="8.52907138161489E-05" ixz="6.73224445510202E-07" iyy="0.000959826064510336" iyz="8.0840859065961E-07" izz="0.00130175668733721"/>
    </inertial>
    <visual>
      <origin rpy="0 0 0" xyz="0 0 0.015"/>
      <geometry>
        <mesh filename="yuna_stl/M6_base_motor.STL"/>
      </geometry>
      <material name="red">
      </material>
    </visual>
    <collision>
      <!--origin
          xyz="0 0 0.015"
          rpy="0 0 0" />
        <geometry>
          <mesh
            filename="yuna_stl/boxed_meshes/base_motor.STL" />
        </geometry-->
      <origin rpy="0 0 0" xyz="0.019940 0.001750 0.015525"/>
      <geometry>
        <box size="0.106400 0.069500 0.031050"/>
      </geometry>
    </collision>
  </link>
  <joint name="leg5__OUTPUT_INTERFACE" type="fixed">
    <origin rpy="0 0 5.75941666667" xyz="-0.205681 0.11875 0"/>
    <parent link="base_link"/>
    <child link="base5__INPUT_INTERFACE"/>
    <axis xyz="0 0 1"/>
    <limit effort="0" velocity="0"/>
  </joint>
  <link name="shoulder5__INPUT_INTERFACE">
    <inertial>
      <origin rpy="0 0 0" xyz="-0.012554 -0.0090693 0.0503697"/>
      <mass value="1.4679"/>
      <inertia ixx="0.00085304" ixy="-4.463E-05" ixz="4.178E-05" iyy="0.0016596" iyz="4.4E-06" izz="0.00113592"/>
    </inertial>
    <visual>
      <origin rpy="0 0 0" xyz="0 0 0"/>
      <geometry>
        <mesh filename="yuna_stl/M6_left_link1_red.STL"/>
      </geometry>
      <material name="grey">
      </material>
    </visual>
    <collision>
      <!--origin
          xyz="0 0 0"
          rpy="0 0 0" />
        <geometry>
          <mesh
            filename="yuna_stl/boxed_meshes/left_link1_red.STL" />
        </geometry-->
      <origin rpy="0 0 0" xyz="-0.019070 -0.014470 0.052500"/>
      <geometry>
        <box size="0.108140 0.04500 0.104000"/>
      </geometry>
    </collision>
  </link>
  <joint name="base5" type="revolute">
    <origin rpy="0 0 3.1415" xyz="0 0 0.03105"/>
    <parent link="base5__INPUT_INTERFACE"/>
    <child link="shoulder5__INPUT_INTERFACE"/>
    <axis xyz="0 0 1"/>
    <dynamics damping=".1" friction="0.2"/>
    <limit effort="100.0" lower="-1.57075" upper="1.57075" velocity="2.208932"/>
  </joint>
  <transmission name="base5_trans">
    <type>transmission_interface/SimpleTransmission</type>
    <joint name="base5">
      <hardwareInterface>hardware_interface/EffortJointInterface</hardwareInterface>
    </joint>
    <actuator name="base5_motor">
      <hardwareInterface>hardware_interface/EffortJointInterface</hardwareInterface>
      <mechanicalReduction>300</mechanicalReduction>
    </actuator>
  </transmission>
  <link name="elbow5__INPUT_INTERFACE">
    <inertial>
      <origin rpy="0 0 0" xyz="0.27885723 0.00143862 -0.00919708"/>
      <mass value="1.58985"/>
      <inertia ixx="0.00087813" ixy="-2.653E-05" ixz="-0.00101493" iyy="0.01121522" iyz="-1.36E-05" izz="0.01137087"/>
    </inertial>
    <visual>
      <origin rpy="0 0 0" xyz="0 0 0"/>
      <geometry>
        <mesh filename="yuna_stl/M6_link2_red.STL"/>
      </geometry>
      <material name="red">
      </material>
    </visual>
    <collision>
      <!--origin
          xyz="0 0 0"
          rpy="0 0 0" />
        <geometry>
          <mesh
            filename="yuna_stl/boxed_meshes/link2_red.STL" />
        </geometry-->
      <origin rpy="0 0 0" xyz="0.005750 0.0 0.018750"/>
      <geometry>
        <box size="0.05950 0.04800 0.037500"/>
      </geometry>
    </collision>
    <collision>
      <origin rpy="0 1.57075 0" xyz="0.159500 0.0 0.02"/>
      <geometry>
        <cylinder length="0.246" radius="0.015811"/>
      </geometry>
    </collision>
    <collision>
      <origin rpy="0 0 0" xyz="0.317750 0.0 0.01875"/>
      <geometry>
        <box size="0.06850 0.06500 0.037500"/>
      </geometry>
    </collision>
    <collision>
      <origin rpy="0.0 0.0 0.0" xyz="0.299560 0.001750 -0.015520"/>
      <geometry>
        <box size="0.106400 0.069500 0.030050"/>
      </geometry>
    </collision>
  </link>
  <joint name="shoulder5" type="revolute">
    <origin rpy="-1.57075 0 0" xyz="0 0.00855 0.055"/>
    <parent link="shoulder5__INPUT_INTERFACE"/>
    <child link="elbow5__INPUT_INTERFACE"/>
    <axis xyz="0 0 1"/>
    <dynamics damping=".1" friction="0.2"/>
    <limit effort="100.0" lower="-1.57075" upper="1.57075" velocity="2.208932"/>
  </joint>
  <transmission name="shoulder5_trans">
    <type>transmission_interface/SimpleTransmission</type>
    <joint name="shoulder5">
      <hardwareInterface>hardware_interface/EffortJointInterface</hardwareInterface>
    </joint>
    <actuator name="shoulder5_motor">
      <hardwareInterface>hardware_interface/EffortJointInterface</hardwareInterface>
      <mechanicalReduction>300</mechanicalReduction>
    </actuator>
  </transmission>
  <link name="leg5__LAST_LINK">
    <inertial>
      <origin rpy="0 0 0" xyz="0.12121923 0 0.01723596"/>
      <mass value="0.229433"/>
      <inertia ixx="7.471E-05" ixy="0" ixz="7.798E-05" iyy="0.00331684" iyz="0" izz="0.0033262"/>
    </inertial>
    <visual>
      <origin rpy="0 0 0" xyz="0 0 0"/>
      <geometry>
        <mesh filename="yuna_stl/M6_link3_red.STL"/>
      </geometry>
      <material name="grey">
      </material>
    </visual>
    <!--collision>
        <origin
          xyz="0 0 0"
          rpy="0 0 0" />
        <geometry>
          <mesh
            filename="yuna_stl/boxed_meshes/link3_red.STL" />
        </geometry>
      </collision-->
    <collision>
      <origin rpy="0 0 0" xyz="0.00575 0.0 0.0185"/>
      <geometry>
        <box size="0.05850 0.04800 0.03650"/>
      </geometry>
    </collision>
    <collision>
      <origin rpy="0.0 1.57075 0.0" xyz="0.15125 0.000 0.020"/>
      <geometry>
        <cylinder length="0.230500" radius="0.015811"/>
      </geometry>
    </collision>
    <collision>
      <origin rpy="0.0 0.0 0.0" xyz="0.28950 0.00 0.02"/>
      <geometry>
        <box size="0.045000 0.047030 0.047030"/>
      </geometry>
    </collision>
  </link>
  <joint name="elbow5" type="revolute">
    <origin rpy="3.1415 0 0" xyz="0.3195 0 -0.03105"/>
    <parent link="elbow5__INPUT_INTERFACE"/>
    <child link="leg5__LAST_LINK"/>
    <axis xyz="0 0 1"/>
    <dynamics damping=".1" friction="0.2"/>
    <limit effort="100.0" lower="-3.1415" upper="3.1415" velocity="2.208932"/>
  </joint>
  <transmission name="elbow5_trans">
    <type>transmission_interface/SimpleTransmission</type>
    <joint name="elbow5">
      <hardwareInterface>hardware_interface/EffortJointInterface</hardwareInterface>
    </joint>
    <actuator name="elbow5_motor">
      <hardwareInterface>hardware_interface/EffortJointInterface</hardwareInterface>
      <mechanicalReduction>300</mechanicalReduction>
    </actuator>
  </transmission>
  <link name="leg5__FOOT">
    <visual>
      <origin rpy="0 0 0" xyz="0 0 0"/>
      <geometry>
        <sphere radius="0.02"/>
      </geometry>
      <material name="orange"/>
    </visual>
    <collision>
      <origin rpy="0 0 0" xyz="0 0 0"/>
      <geometry>
        <sphere radius="0.03"/>
      </geometry>
    </collision>
    <inertial>
      <origin rpy="0 0 0" xyz="0 0 0"/>
      <mass value="0.06"/>
      <inertia ixx="9.6e-06" ixy="0.0" ixz="0.0" iyy="9.6e-06" iyz="0.0" izz="9.6e-06"/>
    </inertial>
  </link>
  <joint name="leg5__FOOT_INTERFACE" type="fixed">
    <origin rpy="0 0 0" xyz="0.31 0 0.02"/>
    <parent link="leg5__LAST_LINK"/>
    <child link="leg5__FOOT"/>
    <axis xyz="0 0 1"/>
    <limit effort="0" velocity="0"/>
  </joint>
  <link name="base2__INPUT_INTERFACE">
    <inertial>
      <origin rpy="0 0 0" xyz="0.015005 0.001775 0.015011"/>
      <mass value="1.2804"/>
      <inertia ixx="0.000533112547871023" ixy="8.52907138161489E-05" ixz="6.73224445510202E-07" iyy="0.000959826064510336" iyz="8.0840859065961E-07" izz="0.00130175668733721"/>
    </inertial>
    <visual>
      <origin rpy="0 0 0" xyz="0 0 0.015"/>
      <geometry>
        <mesh filename="yuna_stl/M6_base_motor.STL"/>
      </geometry>
      <material name="red">
      </material>
    </visual>
    <collision>
      <!--origin
          xyz="0 0 0.015"
          rpy="0 0 0" />
        <geometry>
          <mesh
            filename="yuna_stl/boxed_meshes/base_motor.STL" />
        </geometry-->
      <origin rpy="0 0 0" xyz="0.019940 0.001750 0.015525"/>
      <geometry>
        <box size="0.106400 0.069500 0.031050"/>
      </geometry>
    </collision>
  </link>
  <joint name="leg2__OUTPUT_INTERFACE" type="fixed">
    <origin rpy="0 0 2.61791666667" xyz="0.205681 -0.11875 0"/>
    <parent link="base_link"/>
    <child link="base2__INPUT_INTERFACE"/>
    <axis xyz="0 0 1"/>
    <limit effort="0" velocity="0"/>
  </joint>
  <link name="shoulder2__INPUT_INTERFACE">
    <inertial>
      <origin rpy="0 0 0" xyz="-0.012554 -0.0090693 -0.0503697"/>
      <mass value="1.4679"/>
      <inertia ixx="0.00085304" ixy="-4.463E-05" ixz="-4.178E-05" iyy="0.0016596" iyz="-4.4E-06" izz="0.00113592"/>
    </inertial>
    <visual>
      <origin rpy="0 0 0" xyz="0 0 0"/>
      <geometry>
        <mesh filename="yuna_stl/M6_right_link1_red.STL"/>
      </geometry>
      <material name="grey">
      </material>
    </visual>
    <collision>
      <!--origin
          xyz="0 0 0"
          rpy="0 0 0" />
        <geometry>
          <mesh
            filename="yuna_stl/boxed_meshes/right_link1_red.STL" />
        </geometry-->
      <origin rpy="0 0 0" xyz="0.019070 -0.014470 0.052500"/>
      <geometry>
        <box size="0.108140 0.04500 0.104000"/>
      </geometry>
    </collision>
  </link>
  <joint name="base2" type="revolute">
    <origin rpy="0 0 0" xyz="0 0 0.03105"/>
    <parent link="base2__INPUT_INTERFACE"/>
    <child link="shoulder2__INPUT_INTERFACE"/>
    <axis xyz="0 0 1"/>
    <dynamics damping=".1" friction="0.2"/>
    <limit effort="80.0" lower="-1.57075" upper="1.57075" velocity="2.208932"/>
  </joint>
  <transmission name="base2_trans">
    <type>transmission_interface/SimpleTransmission</type>
    <joint name="base2">
      <hardwareInterface>hardware_interface/EffortJointInterface</hardwareInterface>
    </joint>
    <actuator name="base2_motor">
      <hardwareInterface>hardware_interface/EffortJointInterface</hardwareInterface>
      <mechanicalReduction>300</mechanicalReduction>
    </actuator>
  </transmission>
  <link name="elbow2__INPUT_INTERFACE">
    <inertial>
      <origin rpy="0 0 0" xyz="0.27885723 0.00143862 -0.00919708"/>
      <mass value="1.58985"/>
      <inertia ixx="0.00087813" ixy="-2.653E-05" ixz="-0.00101493" iyy="0.01121522" iyz="-1.36E-05" izz="0.01137087"/>
    </inertial>
    <visual>
      <origin rpy="0 0 0" xyz="0 0 0"/>
      <geometry>
        <mesh filename="yuna_stl/M6_link2_red.STL"/>
      </geometry>
      <material name="red">
      </material>
    </visual>
    <collision>
      <!--origin
          xyz="0 0 0"
          rpy="0 0 0" />
        <geometry>
          <mesh
            filename="yuna_stl/boxed_meshes/link2_red.STL" />
        </geometry-->
      <origin rpy="0 0 0" xyz="0.005750 0.0 0.018750"/>
      <geometry>
        <box size="0.05950 0.04800 0.037500"/>
      </geometry>
    </collision>
    <collision>
      <origin rpy="0 1.57075 0" xyz="0.159500 0.0 0.02"/>
      <geometry>
        <cylinder length="0.246" radius="0.015811"/>
      </geometry>
    </collision>
    <collision>
      <origin rpy="0 0 0" xyz="0.317750 0.0 0.01875"/>
      <geometry>
        <box size="0.06850 0.06500 0.037500"/>
      </geometry>
    </collision>
    <collision>
      <origin rpy="0.0 0.0 0.0" xyz="0.299560 0.001750 -0.015520"/>
      <geometry>
        <box size="0.106400 0.069500 0.030050"/>
      </geometry>
    </collision>
  </link>
  <joint name="shoulder2" type="revolute">
    <origin rpy="1.57075 0 3.1415" xyz="0 0.00855 0.055"/>
    <parent link="shoulder2__INPUT_INTERFACE"/>
    <child link="elbow2__INPUT_INTERFACE"/>
    <axis xyz="0 0 1"/>
    <dynamics damping=".1" friction="0.2"/>
    <limit effort="80.0" lower="-1.57075" upper="1.57075" velocity="2.208932"/>
  </joint>
  <transmission name="shoulder2_trans">
    <type>transmission_interface/SimpleTransmission</type>
    <joint name="shoulder2">
      <hardwareInterface>hardware_interface/EffortJointInterface</hardwareInterface>
    </joint>
    <actuator name="shoulder2_motor">
      <hardwareInterface>hardware_interface/EffortJointInterface</hardwareInterface>
      <mechanicalReduction>300</mechanicalReduction>
    </actuator>
  </transmission>
  <link name="leg2__LAST_LINK">
    <inertial>
      <origin rpy="0 0 0" xyz="0.12121923 0 0.01723596"/>
      <mass value="0.229433"/>
      <inertia ixx="7.471E-05" ixy="0" ixz="7.798E-05" iyy="0.00331684" iyz="0" izz="0.0033262"/>
    </inertial>
    <visual>
      <origin rpy="0 0 0" xyz="0 0 0"/>
      <geometry>
        <mesh filename="yuna_stl/M6_link3_red.STL"/>
      </geometry>
      <material name="grey">
      </material>
    </visual>
    <!--collision>
        <origin
          xyz="0 0 0"
          rpy="0 0 0" />
        <geometry>
          <mesh
            filename="yuna_stl/boxed_meshes/link3_red.STL" />
        </geometry>
      </collision-->
    <collision>
      <origin rpy="0 0 0" xyz="0.00575 0.0 0.0185"/>
      <geometry>
        <box size="0.05850 0.04800 0.03650"/>
      </geometry>
    </collision>
    <collision>
      <origin rpy="0.0 1.57075 0.0" xyz="0.15125 0.000 0.020"/>
      <geometry>
        <cylinder length="0.230500" radius="0.015811"/>
      </geometry>
    </collision>
    <collision>
      <origin rpy="0.0 0.0 0.0" xyz="0.28950 0.00 0.02"/>
      <geometry>
        <box size="0.045000 0.047030 0.047030"/>
      </geometry>
    </collision>
  </link>
  <joint name="elbow2" type="revolute">
    <origin rpy="3.1415 0 0" xyz="0.3195 0 -0.03105"/>
    <parent link="elbow2__INPUT_INTERFACE"/>
    <child link="leg2__LAST_LINK"/>
    <axis xyz="0 0 1"/>
    <dynamics damping=".1" friction="0.2"/>
    <limit effort="80.0" lower="-3.1415" upper="3.1415" velocity="2.208932"/>
  </joint>
  <transmission name="elbow2_trans">
    <type>transmission_interface/SimpleTransmission</type>
    <joint name="elbow2">
      <hardwareInterface>hardware_interface/EffortJointInterface</hardwareInterface>
    </joint>
    <actuator name="elbow2_motor">
      <hardwareInterface>hardware_interface/EffortJointInterface</hardwareInterface>
      <mechanicalReduction>300</mechanicalReduction>
    </actuator>
  </transmission>
  <link name="leg2__FOOT">
    <visual>
      <origin rpy="0 0 0" xyz="0 0 0"/>
      <geometry>
        <sphere radius="0.02"/>
      </geometry>
      <material name="orange"/>
    </visual>
    <collision>
      <origin rpy="0 0 0" xyz="0 0 0"/>
      <geometry>
        <sphere radius="0.03"/>
      </geometry>
    </collision>
    <inertial>
      <origin rpy="0 0 0" xyz="0 0 0"/>
      <mass value="0.06"/>
      <inertia ixx="9.6e-06" ixy="0.0" ixz="0.0" iyy="9.6e-06" iyz="0.0" izz="9.6e-06"/>
    </inertial>
  </link>
  <joint name="leg2__FOOT_INTERFACE" type="fixed">
    <origin rpy="0 0 0" xyz="0.31 0 0.02"/>
    <parent link="leg2__LAST_LINK"/>
    <child link="leg2__FOOT"/>
    <axis xyz="0 0 1"/>
    <limit effort="0" velocity="0"/>
  </joint>
  <link name="base4__INPUT_INTERFACE">
    <inertial>
      <origin rpy="0 0 0" xyz="0.015005 0.001775 0.015011"/>
      <mass value="1.2804"/>
      <inertia ixx="0.000533112547871023" ixy="8.52907138161489E-05" ixz="6.73224445510202E-07" iyy="0.000959826064510336" iyz="8.0840859065961E-07" izz="0.00130175668733721"/>
    </inertial>
    <visual>
      <origin rpy="0 0 0" xyz="0 0 0.015"/>
      <geometry>
        <mesh filename="yuna_stl/M6_base_motor.STL"/>
      </geometry>
      <material name="red">
      </material>
    </visual>
    <collision>
      <!--origin
          xyz="0 0 0.015"
          rpy="0 0 0" />
        <geometry>
          <mesh
            filename="yuna_stl/boxed_meshes/base_motor.STL" />
        </geometry-->
      <origin rpy="0 0 0" xyz="0.019940 0.001750 0.015525"/>
      <geometry>
        <box size="0.106400 0.069500 0.031050"/>
      </geometry>
    </collision>
  </link>
  <joint name="leg4__OUTPUT_INTERFACE" type="fixed">
    <origin rpy="0 0 1.57075" xyz="0 -0.1875 0"/>
    <parent link="base_link"/>
    <child link="base4__INPUT_INTERFACE"/>
    <axis xyz="0 0 1"/>
    <limit effort="0" velocity="0"/>
  </joint>
  <link name="shoulder4__INPUT_INTERFACE">
    <inertial>
      <origin rpy="0 0 0" xyz="-0.012554 -0.0090693 -0.0503697"/>
      <mass value="1.4679"/>
      <inertia ixx="0.00085304" ixy="-4.463E-05" ixz="-4.178E-05" iyy="0.0016596" iyz="-4.4E-06" izz="0.00113592"/>
    </inertial>
    <visual>
      <origin rpy="0 0 0" xyz="0 0 0"/>
      <geometry>
        <mesh filename="yuna_stl/M6_right_link1_red.STL"/>
      </geometry>
      <material name="grey">
      </material>
    </visual>
    <collision>
      <!--origin
          xyz="0 0 0"
          rpy="0 0 0" />
        <geometry>
          <mesh
            filename="yuna_stl/boxed_meshes/right_link1_red.STL" />
        </geometry-->
      <origin rpy="0 0 0" xyz="0.019070 -0.014470 0.052500"/>
      <geometry>
        <box size="0.108140 0.04500 0.104000"/>
      </geometry>
    </collision>
  </link>
  <joint name="base4" type="revolute">
    <origin rpy="0 0 0" xyz="0 0 0.03105"/>
    <parent link="base4__INPUT_INTERFACE"/>
    <child link="shoulder4__INPUT_INTERFACE"/>
    <axis xyz="0 0 1"/>
    <dynamics damping=".1" friction="0.2"/>
    <limit effort="100.0" lower="-1.57075" upper="1.57075" velocity="2.208932"/>
  </joint>
  <transmission name="base4_trans">
    <type>transmission_interface/SimpleTransmission</type>
    <joint name="base4">
      <hardwareInterface>hardware_interface/EffortJointInterface</hardwareInterface>
    </joint>
    <actuator name="base4_motor">
      <hardwareInterface>hardware_interface/EffortJointInterface</hardwareInterface>
      <mechanicalReduction>300</mechanicalReduction>
    </actuator>
  </transmission>
  <link name="elbow4__INPUT_INTERFACE">
    <inertial>
      <origin rpy="0 0 0" xyz="0.27885723 0.00143862 -0.00919708"/>
      <mass value="1.58985"/>
      <inertia ixx="0.00087813" ixy="-2.653E-05" ixz="-0.00101493" iyy="0.01121522" iyz="-1.36E-05" izz="0.01137087"/>
    </inertial>
    <visual>
      <origin rpy="0 0 0" xyz="0 0 0"/>
      <geometry>
        <mesh filename="yuna_stl/M6_link2_red.STL"/>
      </geometry>
      <material name="red">
      </material>
    </visual>
    <collision>
      <!--origin
          xyz="0 0 0"
          rpy="0 0 0" />
        <geometry>
          <mesh
            filename="yuna_stl/boxed_meshes/link2_red.STL" />
        </geometry-->
      <origin rpy="0 0 0" xyz="0.005750 0.0 0.018750"/>
      <geometry>
        <box size="0.05950 0.04800 0.037500"/>
      </geometry>
    </collision>
    <collision>
      <origin rpy="0 1.57075 0" xyz="0.159500 0.0 0.02"/>
      <geometry>
        <cylinder length="0.246" radius="0.015811"/>
      </geometry>
    </collision>
    <collision>
      <origin rpy="0 0 0" xyz="0.317750 0.0 0.01875"/>
      <geometry>
        <box size="0.06850 0.06500 0.037500"/>
      </geometry>
    </collision>
    <collision>
      <origin rpy="0.0 0.0 0.0" xyz="0.299560 0.001750 -0.015520"/>
      <geometry>
        <box size="0.106400 0.069500 0.030050"/>
      </geometry>
    </collision>
  </link>
  <joint name="shoulder4" type="revolute">
    <origin rpy="1.57075 0 3.1415" xyz="0 0.00855 0.055"/>
    <parent link="shoulder4__INPUT_INTERFACE"/>
    <child link="elbow4__INPUT_INTERFACE"/>
    <axis xyz="0 0 1"/>
    <dynamics damping=".1" friction="0.2"/>
    <limit effort="100.0" lower="-1.57075" upper="1.57075" velocity="2.208932"/>
  </joint>
  <transmission name="shoulder4_trans">
    <type>transmission_interface/SimpleTransmission</type>
    <joint name="shoulder4">
      <hardwareInterface>hardware_interface/EffortJointInterface</hardwareInterface>
    </joint>
    <actuator name="shoulder4_motor">
      <hardwareInterface>hardware_interface/EffortJointInterface</hardwareInterface>
      <mechanicalReduction>300</mechanicalReduction>
    </actuator>
  </transmission>
  <link name="leg4__LAST_LINK">
    <inertial>
      <origin rpy="0 0 0" xyz="0.12121923 0 0.01723596"/>
      <mass value="0.229433"/>
      <inertia ixx="7.471E-05" ixy="0" ixz="7.798E-05" iyy="0.00331684" iyz="0" izz="0.0033262"/>
    </inertial>
    <visual>
      <origin rpy="0 0 0" xyz="0 0 0"/>
      <geometry>
        <mesh filename="yuna_stl/M6_link3_red.STL"/>
      </geometry>
      <material name="grey">
      </material>
    </visual>
    <!--collision>
        <origin
          xyz="0 0 0"
          rpy="0 0 0" />
        <geometry>
          <mesh
            filename="yuna_stl/boxed_meshes/link3_red.STL" />
        </geometry>
      </collision-->
    <collision>
      <origin rpy="0 0 0" xyz="0.00575 0.0 0.0185"/>
      <geometry>
        <box size="0.05850 0.04800 0.03650"/>
      </geometry>
    </collision>
    <collision>
      <origin rpy="0.0 1.57075 0.0" xyz="0.15125 0.000 0.020"/>
      <geometry>
        <cylinder length="0.230500" radius="0.015811"/>
      </geometry>
    </collision>
    <collision>
      <origin rpy="0.0 0.0 0.0" xyz="0.28950 0.00 0.02"/>
      <geometry>
        <box size="0.045000 0.047030 0.047030"/>
      </geometry>
    </collision>
  </link>
  <joint name="elbow4" type="revolute">
    <origin rpy="3.1415 0 0" xyz="0.3195 0 -0.03105"/>
    <parent link="elbow4__INPUT_INTERFACE"/>
    <child link="leg4__LAST_LINK"/>
    <axis xyz="0 0 1"/>
    <dynamics damping=".1" friction="0.2"/>
    <limit effort="100.0" lower="-3.1415" upper="3.1415" velocity="2.208932"/>
  </joint>
  <transmission name="elbow4_trans">
    <type>transmission_interface/SimpleTransmission</type>
    <joint name="elbow4">
      <hardwareInterface>hardware_interface/EffortJointInterface</hardwareInterface>
    </joint>
    <actuator name="elbow4_motor">
      <hardwareInterface>hardware_interface/EffortJointInterface</hardwareInterface>
      <mechanicalReduction>300</mechanicalReduction>
    </actuator>
  </transmission>
  <link name="leg4__FOOT">
    <visual>
      <origin rpy="0 0 0" xyz="0 0 0"/>
      <geometry>
        <sphere radius="0.02"/>
      </geometry>
      <material name="orange"/>
    </visual>
    <collision>
      <origin rpy="0 0 0" xyz="0 0 0"/>
      <geometry>
        <sphere radius="0.03"/>
      </geometry>
    </collision>
    <inertial>
      <origin rpy="0 0 0" xyz="0 0 0"/>
      <mass value="0.06"/>
      <inertia ixx="9.6e-06" ixy="0.0" ixz="0.0" iyy="9.6e-06" iyz="0.0" izz="9.6e-06"/>
    </inertial>
  </link>
  <joint name="leg4__FOOT_INTERFACE" type="fixed">
    <origin rpy="0 0 0" xyz="0.31 0 0.02"/>
    <parent link="leg4__LAST_LINK"/>
    <child link="leg4__FOOT"/>
    <axis xyz="0 0 1"/>
    <limit effort="0" velocity="0"/>
  </joint>
  <link name="base6__INPUT_INTERFACE">
    <inertial>
      <origin rpy="0 0 0" xyz="0.015005 0.001775 0.015011"/>
      <mass value="1.2804"/>
      <inertia ixx="0.000533112547871023" ixy="8.52907138161489E-05" ixz="6.73224445510202E-07" iyy="0.000959826064510336" iyz="8.0840859065961E-07" izz="0.00130175668733721"/>
    </inertial>
    <visual>
      <origin rpy="0 0 0" xyz="0 0 0.015"/>
      <geometry>
        <mesh filename="yuna_stl/M6_base_motor.STL"/>
      </geometry>
      <material name="red">
      </material>
    </visual>
    <collision>
      <!--origin
          xyz="0 0 0.015"
          rpy="0 0 0" />
        <geometry>
          <mesh
            filename="yuna_stl/boxed_meshes/base_motor.STL" />
        </geometry-->
      <origin rpy="0 0 0" xyz="0.019940 0.001750 0.015525"/>
      <geometry>
        <box size="0.106400 0.069500 0.031050"/>
      </geometry>
    </collision>
  </link>
  <joint name="leg6__OUTPUT_INTERFACE" type="fixed">
    <origin rpy="0 0 0.523583333333" xyz="-0.205681 -0.11875 0"/>
    <parent link="base_link"/>
    <child link="base6__INPUT_INTERFACE"/>
    <axis xyz="0 0 1"/>
    <limit effort="0" velocity="0"/>
  </joint>
  <link name="shoulder6__INPUT_INTERFACE">
    <inertial>
      <origin rpy="0 0 0" xyz="-0.012554 -0.0090693 -0.0503697"/>
      <mass value="1.4679"/>
      <inertia ixx="0.00085304" ixy="-4.463E-05" ixz="-4.178E-05" iyy="0.0016596" iyz="-4.4E-06" izz="0.00113592"/>
    </inertial>
    <visual>
      <origin rpy="0 0 0" xyz="0 0 0"/>
      <geometry>
        <mesh filename="yuna_stl/M6_right_link1_red.STL"/>
      </geometry>
      <material name="grey">
      </material>
    </visual>
    <collision>
      <!--origin
          xyz="0 0 0"
          rpy="0 0 0" />
        <geometry>
          <mesh
            filename="yuna_stl/boxed_meshes/right_link1_red.STL" />
        </geometry-->
      <origin rpy="0 0 0" xyz="0.019070 -0.014470 0.052500"/>
      <geometry>
        <box size="0.108140 0.04500 0.104000"/>
      </geometry>
    </collision>
  </link>
  <joint name="base6" type="revolute">
    <origin rpy="0 0 0" xyz="0 0 0.03105"/>
    <parent link="base6__INPUT_INTERFACE"/>
    <child link="shoulder6__INPUT_INTERFACE"/>
    <axis xyz="0 0 1"/>
    <dynamics damping=".1" friction="0.2"/>
    <limit effort="100.0" lower="-1.57075" upper="1.57075" velocity="2.208932"/>
  </joint>
  <transmission name="base6_trans">
    <type>transmission_interface/SimpleTransmission</type>
    <joint name="base6">
      <hardwareInterface>hardware_interface/EffortJointInterface</hardwareInterface>
    </joint>
    <actuator name="base6_motor">
      <hardwareInterface>hardware_interface/EffortJointInterface</hardwareInterface>
      <mechanicalReduction>300</mechanicalReduction>
    </actuator>
  </transmission>
  <link name="elbow6__INPUT_INTERFACE">
    <inertial>
      <origin rpy="0 0 0" xyz="0.27885723 0.00143862 -0.00919708"/>
      <mass value="1.58985"/>
      <inertia ixx="0.00087813" ixy="-2.653E-05" ixz="-0.00101493" iyy="0.01121522" iyz="-1.36E-05" izz="0.01137087"/>
    </inertial>
    <visual>
      <origin rpy="0 0 0" xyz="0 0 0"/>
      <geometry>
        <mesh filename="yuna_stl/M6_link2_red.STL"/>
      </geometry>
      <material name="red">
      </material>
    </visual>
    <collision>
      <!--origin
          xyz="0 0 0"
          rpy="0 0 0" />
        <geometry>
          <mesh
            filename="yuna_stl/boxed_meshes/link2_red.STL" />
        </geometry-->
      <origin rpy="0 0 0" xyz="0.005750 0.0 0.018750"/>
      <geometry>
        <box size="0.05950 0.04800 0.037500"/>
      </geometry>
    </collision>
    <collision>
      <origin rpy="0 1.57075 0" xyz="0.159500 0.0 0.02"/>
      <geometry>
        <cylinder length="0.246" radius="0.015811"/>
      </geometry>
    </collision>
    <collision>
      <origin rpy="0 0 0" xyz="0.317750 0.0 0.01875"/>
      <geometry>
        <box size="0.06850 0.06500 0.037500"/>
      </geometry>
    </collision>
    <collision>
      <origin rpy="0.0 0.0 0.0" xyz="0.299560 0.001750 -0.015520"/>
      <geometry>
        <box size="0.106400 0.069500 0.030050"/>
      </geometry>
    </collision>
  </link>
  <joint name="shoulder6" type="revolute">
    <origin rpy="1.57075 0 3.1415" xyz="0 0.00855 0.055"/>
    <parent link="shoulder6__INPUT_INTERFACE"/>
    <child link="elbow6__INPUT_INTERFACE"/>
    <axis xyz="0 0 1"/>
    <dynamics damping=".1" friction="0.2"/>
    <limit effort="100.0" lower="-1.57075" upper="1.57075" velocity="2.208932"/>
  </joint>
  <transmission name="shoulder6_trans">
    <type>transmission_interface/SimpleTransmission</type>
    <joint name="shoulder6">
      <hardwareInterface>hardware_interface/EffortJointInterface</hardwareInterface>
    </joint>
    <actuator name="shoulder6_motor">
      <hardwareInterface>hardware_interface/EffortJointInterface</hardwareInterface>
      <mechanicalReduction>300</mechanicalReduction>
    </actuator>
  </transmission>
  <link name="leg6__LAST_LINK">
    <inertial>
      <origin rpy="0 0 0" xyz="0.12121923 0 0.01723596"/>
      <mass value="0.229433"/>
      <inertia ixx="7.471E-05" ixy="0" ixz="7.798E-05" iyy="0.00331684" iyz="0" izz="0.0033262"/>
    </inertial>
    <visual>
      <origin rpy="0 0 0" xyz="0 0 0"/>
      <geometry>
        <mesh filename="yuna_stl/M6_link3_red.STL"/>
      </geometry>
      <material name="grey">
      </material>
    </visual>
    <!--collision>
        <origin
          xyz="0 0 0"
          rpy="0 0 0" />
        <geometry>
          <mesh
            filename="yuna_stl/boxed_meshes/link3_red.STL" />
        </geometry>
      </collision-->
    <collision>
      <origin rpy="0 0 0" xyz="0.00575 0.0 0.0185"/>
      <geometry>
        <box size="0.05850 0.04800 0.03650"/>
      </geometry>
    </collision>
    <collision>
      <origin rpy="0.0 1.57075 0.0" xyz="0.15125 0.000 0.020"/>
      <geometry>
        <cylinder length="0.230500" radius="0.015811"/>
      </geometry>
    </collision>
    <collision>
      <origin rpy="0.0 0.0 0.0" xyz="0.28950 0.00 0.02"/>
      <geometry>
        <box size="0.045000 0.047030 0.047030"/>
      </geometry>
    </collision>
  </link>
  <joint name="elbow6" type="revolute">
    <origin rpy="3.1415 0 0" xyz="0.3195 0 -0.03105"/>
    <parent link="elbow6__INPUT_INTERFACE"/>
    <child link="leg6__LAST_LINK"/>
    <axis xyz="0 0 1"/>
    <dynamics damping=".1" friction="0.2"/>
    <limit effort="100.0" lower="-3.1415" upper="3.1415" velocity="2.208932"/>
  </joint>
  <transmission name="elbow6_trans">
    <type>transmission_interface/SimpleTransmission</type>
    <joint name="elbow6">
      <hardwareInterface>hardware_interface/EffortJointInterface</hardwareInterface>
    </joint>
    <actuator name="elbow6_motor">
      <hardwareInterface>hardware_interface/EffortJointInterface</hardwareInterface>
      <mechanicalReduction>300</mechanicalReduction>
    </actuator>
  </transmission>
  <link name="leg6__FOOT">
    <visual>
      <origin rpy="0 0 0" xyz="0 0 0"/>
      <geometry>
        <sphere radius="0.02"/>
      </geometry>
      <material name="orange"/>
    </visual>
    <collision>
      <origin rpy="0 0 0" xyz="0 0 0"/>
      <geometry>
        <sphere radius="0.03"/>
      </geometry>
    </collision>
    <inertial>
      <origin rpy="0 0 0" xyz="0 0 0"/>
      <mass value="0.06"/>
      <inertia ixx="9.6e-06" ixy="0.0" ixz="0.0" iyy="9.6e-06" iyz="0.0" izz="9.6e-06"/>
    </inertial>
  </link>
  <joint name="leg6__FOOT_INTERFACE" type="fixed">
    <origin rpy="0 0 0" xyz="0.31 0 0.02"/>
    <parent link="leg6__LAST_LINK"/>
    <child link="leg6__FOOT"/>
    <axis xyz="0 0 1"/>
    <limit effort="0" velocity="0"/>
  </joint>
</robot>

